Workbook

Sheet RAW_Dump_ERP_Q3_Q4
A1: ID_TRANSAZIONE | B1: DATA_ORDINE | C1: CATEGORIA | D1: PRODOTTO | E1: REGIONE | F1: COMMERCIALE | G1: QUANTITA | H1: PREZZO_UNITARIO | I1: COSTO_UNITARIO
A2: ORD-2026-1001 | B2: 2026-09-11 | C2: Software | D2: ERP Module Analytics (Lic.) | E2: Nord | F2: G. Bianchi | G2: 19 | H2: 850 | I2: 200
A3: ORD-2026-1002 | B3: 09/10/2026 | C3: Arredo | D3: Supporto Monitor Doppio | E3: Centro | F3: G. Bianchi | G3: 21 | H3: 70 | I3: 32
A4: ORD-2026-1003 | B4: 2026-07-19 | C4: Software | D4: Antivirus Enterprise (Lic.) | E4: isole | F4: L. Esposito | G4: 44 | H4: 54 | I4: 15
A5: ORD-2026-1004 | B5: 2026-06-21 | C5: Arredo | D5: Supporto Monitor Doppio | E5: Centro | F5: G. Bianchi | G5: 9 | H5: 70 | I5: 32
A6: ORD-2026-1005 | B6: 08/06/2026 | C6: Arredo | D6: Scrivania Ergonomica | E6: Isole | F6: F. Russo | G6: 2 | H6: 237.5 | I6: 160
A7: ORD-2026-1006 | B7: 2026-10-24 | C7: Arredo | D7: Sedia Operativa Mesh | E7: Centro | G7: 23 | H7: 162 | I7: 110
A8: ORD-2026-1007 | B8: 2026-08-21 | C8: Arredo | D8: Scrivania Ergonomica | E8: Isole | F8: E. Ferrari | G8: 41 | H8: 212.5 | I8: 160
A9: ORD-2026-1008 | B9: 2026-08-27 | C9: Software | D9: ERP Module Analytics (Lic.) | E9: Isole | F9: A. Verdi | G9: 35 | H9: 850 | I9: 200
A10: ORD-2026-1009 | B10: 2026-06-28 | C10: Arredo | D10: Scrivania Ergonomica | E10: sud | F10: L. Esposito | G10: 24 | H10: 212.5 | I10: 160
A11: ORD-2026-1010 | B11: 2026-09-09 | C11: Software | D11: Suite Cloud Business (Lic.) | E11: Sud | F11: L. Esposito | H11: 500 | I11: 120
A12: ORD-2026-1011 | B12: 2026-08-02 | C12: Elettronica | D12: Tastiera Meccanica RGB | E12: Isole | F12: L. Esposito | G12: 37 | H12: 80.75 | I12: 40
A13: ORD-2026-1012 | B13: 10-08-2026 | C13: Arredo | D13: Supporto Monitor Doppio | E13: Nord | F13: L. Esposito | G13: 6 | H13: 63 | I13: 32
A14: ORD-2026-1013 | B14: 2026-08-14 | C14: Software | D14: Suite Cloud Business (Lic.) | E14: Nord | G14: 27 | H14: 475 | I14: 120
A15: ORD-2026-1014 | B15: 2026-10-15 | C15: Elettronica | D15: Monitor 27" 4K | E15: Isole | F15: A. Verdi | G15: 32 | H15: 320 | I15: 210
A16: ORD-2026-1015 | B16: 12-06-2026 | D16: Lampada LED Scrivania | E16: Nord | F16: M. Rossi | G16: 2 | H16: 45 | I16: 20
A17: ORD-2026-1016 | B17: 07-10-2026 | C17: Arredo | D17: Scrivania Ergonomica | E17: Isole | F17: L. Esposito | G17: 32 | H17: 225 | I17: 160
A18: ORD-2026-1017 | B18: 2026-07-08 | C18: Arredo | D18: Sedia Operativa Mesh | E18: Sud | F18: M. Rossi | G18: 9 | H18: 162 | I18: 110
A19: ORD-2026-1018 | B19: 2026-10-25 | C19: Software | D19: ERP Module Analytics (Lic.) | E19: Sud | F19: F. Russo | G19: 41 | H19: 850 | I19: 200
A20: ORD-2026-1019 | B20: 2026-06-11 | C20: Elettronica | D20: Auricolari Wireless Pro | E20: Centro | F20: G. Bianchi | G20: 35 | H20: 76.5 | I20: 45
A21: ORD-2026-1020 | B21: 21-09-2026 | C21: Arredo | D21: Supporto Monitor Doppio | E21: Isole | F21: A. Verdi | G21: 9 | H21: 70 | I21: 32
A22: ORD-2026-1021 | B22: 2026-07-24 | C22: Software | D22: Suite Cloud Business (Lic.) | E22: Centro | F22: F. Russo | G22: 35 | H22: 475 | I22: 120
A23: ORD-2026-1022 | B23: 2026-09-18 | C23: Arredo | D23: Lampada LED Scrivania | E23: Nord | F23: F. Russo | G23: 33 | H23: 40.5 | I23: 20
A24: ORD-2026-1023 | B24: 2026-10-06 | C24: Software | D24: Suite Cloud Business (Lic.) | E24: Isole | F24: F. Russo | G24: 22 | H24: 475 | I24: 120
A25: ORD-2026-1024 | B25: 2026-06-08 | C25: Arredo | D25: Scrivania Ergonomica | E25: Isole | F25: M. Rossi | H25: 225 | I25: 160
A26: ORD-2026-1025 | B26: 19/07/2026 | C26: Arredo | D26: Scrivania Ergonomica | E26: Centro | F26: A. Verdi | G26: 41 | H26: 212.5 | I26: 160
A27: ORD-2026-1026 | B27: 2026-09-07 | C27: Software | D27: Suite Cloud Business (Lic.) | E27: Sud | F27: M. Rossi | G27: 3 | H27: 500 | I27: 120
A28: ORD-2026-1027 | B28: 12/09/2026 | C28: Arredo | D28: Supporto Monitor Doppio | E28: Sud | F28: G. Bianchi | G28: 27 | H28: 70 | I28: 32
A29: ORD-2026-1028 | B29: 2026-07-13 | D29: Suite Cloud Business (Lic.) | E29: Centro | F29: A. Verdi | G29: 25 | H29: 425 | I29: 120
A30: ORD-2026-1029 | B30: 2026-06-20 | C30: Arredo | D30: Supporto Monitor Doppio | E30: sud | F30: F. Russo | G30: 34 | H30: 70 | I30: 32
A31: ORD-2026-1030 | B31: 2026-08-02 | C31: Arredo | D31: Sedia Operativa Mesh | E31: Nord | F31: F. Russo | G31: 42 | H31: 171 | I31: 110
A32: ORD-2026-1031 | B32: 2026-06-08 | C32: Elettronica | D32: Tastiera Meccanica RGB | E32: Isole | F32: F. Russo | G32: 30 | H32: 95 | I32: 40
A33: ORD-2026-1032 | B33: 2026-10-02 | C33: Software | D33: Suite Cloud Business (Lic.) | E33: Sud | F33: F. Russo | G33: 26 | H33: 425 | I33: 120
A34: ORD-2026-1033 | B34: 2026-10-18 | C34: Arredo | D34: Sedia Operativa Mesh | E34: Centro | F34: L. Esposito | G34: 25 | H34: 153 | I34: 110
A35: ORD-2026-1034 | B35: 2026-08-08 | C35: Software | D35: ERP Module Analytics (Lic.) | E35: Isole | G35: 37 | H35: 807.5 | I35: 200
A36: ORD-2026-1035 | B36: 2026-09-02 | C36: Elettronica | D36: Tastiera Meccanica RGB | E36: centro | F36: E. Ferrari | G36: 39 | H36: 85.5 | I36: 40
A37: ORD-2026-1036 | B37: 2026-06-10 | C37: Arredo | D37: Supporto Monitor Doppio | E37: Centro | F37: A. Verdi | G37: 32 | H37: 70 | I37: 32
A38: ORD-2026-1037 | B38: 2026-08-19 | C38: Elettronica | D38: Tastiera Meccanica RGB | E38: Sud | F38: F. Russo | G38: 24 | H38: 85.5 | I38: 40
A39: ORD-2026-1038 | B39: 2026-09-09 | C39: Elettronica | D39: Smart Hub X1 | E39: Sud | F39: F. Russo | G39: 29 | H39: 102 | I39: 75
A40: ORD-2026-1039 | B40: 2026-07-05 | C40: Arredo | D40: Supporto Monitor Doppio | E40: Centro | F40: G. Bianchi | G40: 34 | H40: 70 | I40: 32
...

Sheet LISTA_PRODOTTI
A1: CATEGORIA | B1: PRODOTTO
A2: Software | B2: Antivirus Enterprise (Lic.)
A3: Elettronica | B3: Auricolari Wireless Pro
A4: Software | B4: ERP Module Analytics (Lic.)
A5: Arredo | B5: Lampada LED Scrivania
A6: Elettronica | B6: Monitor 27" 4K
A7: Arredo | B7: Scrivania Ergonomica
A8: Arredo | B8: Sedia Operativa Mesh
A9: Elettronica | B9: Smart Hub X1
A10: Software | B10: Suite Cloud Business (Lic.)
A11: Arredo | B11: Supporto Monitor Doppio
A12: Elettronica | B12: Tastiera Meccanica RGB
A13: Elettronica | B13: Webcam Full HD

Sheet CLEAN_Dump_ERP_Q3_Q4 
A1: ID_TRANSAZIONE | B1: DATA_ORDINE | C1: CATEGORIA | D1: PRODOTTO | E1: REGIONE | F1: COMMERCIALE | G1: QUANTITA | H1: PREZZO_UNITARIO | I1: COSTO_UNITARIO | J1: TOT_REVENUE | K1: TOT_COST | L1: PROFIT MARGIN (eur) | M1: PROFIT MARGIN (%)
A2: ORD-2026-1001 | B2: 46276 | C2: =_xlfn.XLOOKUP(D2, LISTA_PRODOTTI!$B$2:$B$13, LISTA_PRODOTTI!$A$2:$A$13) -> Software | D2: ERP Module Analytics (Lic.) | E2: Nord | F2: G. Bianchi | G2: 19 | H2: 850 | I2: 200 | J2: =H2*G2 -> 16150 | K2: =I2*G2 -> 3800 | L2: =J2-K2 -> 12350 | M2: =IF(AND(J2<>0, K2<>0), Table1[[#This Row],[PROFIT MARGIN (eur)]]/K2, 0) -> 3.25
A3: ORD-2026-1002 | B3: 46304 | C3: =_xlfn.XLOOKUP(D3, LISTA_PRODOTTI!$B$2:$B$13, LISTA_PRODOTTI!$A$2:$A$13) -> Arredo | D3: Supporto Monitor Doppio | E3: Centro | F3: G. Bianchi | G3: 21 | H3: 70 | I3: 32 | J3: =H3*G3 -> 1470 | K3: =I3*G3 -> 672 | L3: =J3-K3 -> 798 | M3: =IF(AND(J3<>0, K3<>0), Table1[[#This Row],[PROFIT MARGIN (eur)]]/K3, 0) -> 1.1875
A4: ORD-2026-1003 | B4: 46222 | C4: =_xlfn.XLOOKUP(D4, LISTA_PRODOTTI!$B$2:$B$13, LISTA_PRODOTTI!$A$2:$A$13) -> Software | D4: Antivirus Enterprise (Lic.) | E4: Isole | F4: L. Esposito | G4: 44 | H4: 54 | I4: 15 | J4: =H4*G4 -> 2376 | K4: =I4*G4 -> 660 | L4: =J4-K4 -> 1716 | M4: =IF(AND(J4<>0, K4<>0), Table1[[#This Row],[PROFIT MARGIN (eur)]]/K4, 0) -> 2.6
A5: ORD-2026-1004 | B5: 46194 | C5: =_xlfn.XLOOKUP(D5, LISTA_PRODOTTI!$B$2:$B$13, LISTA_PRODOTTI!$A$2:$A$13) -> Arredo | D5: Supporto Monitor Doppio | E5: Centro | F5: G. Bianchi | G5: 9 | H5: 70 | I5: 32 | J5: =H5*G5 -> 630 | K5: =I5*G5 -> 288 | L5: =J5-K5 -> 342 | M5: =IF(AND(J5<>0, K5<>0), Table1[[#This Row],[PROFIT MARGIN (eur)]]/K5, 0) -> 1.1875
A6: ORD-2026-1005 | B6: 46181 | C6: =_xlfn.XLOOKUP(D6, LISTA_PRODOTTI!$B$2:$B$13, LISTA_PRODOTTI!$A$2:$A$13) -> Arredo | D6: Scrivania Ergonomica | E6: Isole | F6: F. Russo | G6: 2 | H6: 237.5 | I6: 160 | J6: =H6*G6 -> 475 | K6: =I6*G6 -> 320 | L6: =J6-K6 -> 155 | M6: =IF(AND(J6<>0, K6<>0), Table1[[#This Row],[PROFIT MARGIN (eur)]]/K6, 0) -> 0.484375
A7: ORD-2026-1006 | B7: 46319 | C7: =_xlfn.XLOOKUP(D7, LISTA_PRODOTTI!$B$2:$B$13, LISTA_PRODOTTI!$A$2:$A$13) -> Arredo | D7: Sedia Operativa Mesh | E7: Centro | F7: Non Disponibile | G7: 23 | H7: 162 | I7: 110 | J7: =H7*G7 -> 3726 | K7: =I7*G7 -> 2530 | L7: =J7-K7 -> 1196 | M7: =IF(AND(J7<>0, K7<>0), Table1[[#This Row],[PROFIT MARGIN (eur)]]/K7, 0) -> 0.47272727
A8: ORD-2026-1007 | B8: 46255 | C8: =_xlfn.XLOOKUP(D8, LISTA_PRODOTTI!$B$2:$B$13, LISTA_PRODOTTI!$A$2:$A$13) -> Arredo | D8: Scrivania Ergonomica | E8: Isole | F8: E. Ferrari | G8: 41 | H8: 212.5 | I8: 160 | J8: =H8*G8 -> 8712.5 | K8: =I8*G8 -> 6560 | L8: =J8-K8 -> 2152.5 | M8: =IF(AND(J8<>0, K8<>0), Table1[[#This Row],[PROFIT MARGIN (eur)]]/K8, 0) -> 0.328125
A9: ORD-2026-1008 | B9: 46261 | C9: =_xlfn.XLOOKUP(D9, LISTA_PRODOTTI!$B$2:$B$13, LISTA_PRODOTTI!$A$2:$A$13) -> Software | D9: ERP Module Analytics (Lic.) | E9: Isole | F9: A. Verdi | G9: 35 | H9: 850 | I9: 200 | J9: =H9*G9 -> 29750 | K9: =I9*G9 -> 7000 | L9: =J9-K9 -> 22750 | M9: =IF(AND(J9<>0, K9<>0), Table1[[#This Row],[PROFIT MARGIN (eur)]]/K9, 0) -> 3.25
A10: ORD-2026-1009 | B10: 46201 | C10: =_xlfn.XLOOKUP(D10, LISTA_PRODOTTI!$B$2:$B$13, LISTA_PRODOTTI!$A$2:$A$13) -> Arredo | D10: Scrivania Ergonomica | E10: Sud | F10: L. Esposito | G10: 24 | H10: 212.5 | I10: 160 | J10: =H10*G10 -> 5100 | K10: =I10*G10 -> 3840 | L10: =J10-K10 -> 1260 | M10: =IF(AND(J10<>0, K10<>0), Table1[[#This Row],[PROFIT MARGIN (eur)]]/K10, 0) -> 0.328125
A11: ORD-2026-1010 | B11: 46274 | C11: =_xlfn.XLOOKUP(D11, LISTA_PRODOTTI!$B$2:$B$13, LISTA_PRODOTTI!$A$2:$A$13) -> Software | D11: Suite Cloud Business (Lic.) | E11: Sud | F11: L. Esposito | G11: 0 | H11: 500 | I11: 120 | J11: =H11*G11 -> 0 | K11: =I11*G11 -> 0 | L11: =J11-K11 -> 0 | M11: =IF(AND(J11<>0, K11<>0), Table1[[#This Row],[PROFIT MARGIN (eur)]]/K11, 0) -> 0
A12: ORD-2026-1011 | B12: 46236 | C12: =_xlfn.XLOOKUP(D12, LISTA_PRODOTTI!$B$2:$B$13, LISTA_PRODOTTI!$A$2:$A$13) -> Elettronica | D12: Tastiera Meccanica RGB | E12: Isole | F12: L. Esposito | G12: 37 | H12: 80.75 | I12: 40 | J12: =H12*G12 -> 2987.75 | K12: =I12*G12 -> 1480 | L12: =J12-K12 -> 1507.75 | M12: =IF(AND(J12<>0, K12<>0), Table1[[#This Row],[PROFIT MARGIN (eur)]]/K12, 0) -> 1.01875
A13: ORD-2026-1012 | B13: 46244 | C13: =_xlfn.XLOOKUP(D13, LISTA_PRODOTTI!$B$2:$B$13, LISTA_PRODOTTI!$A$2:$A$13) -> Arredo | D13: Supporto Monitor Doppio | E13: Nord | F13: L. Esposito | G13: 6 | H13: 63 | I13: 32 | J13: =H13*G13 -> 378 | K13: =I13*G13 -> 192 | L13: =J13-K13 -> 186 | M13: =IF(AND(J13<>0, K13<>0), Table1[[#This Row],[PROFIT MARGIN (eur)]]/K13, 0) -> 0.96875
... A181: ORD-2026-1180 | B181: 46312 | C181: =_xlfn.XLOOKUP(D181, LISTA_PRODOTTI!$B$2:$B$13, LISTA_PRODOTTI!$A$2:$A$13) -> Software | D181: Suite Cloud Business (Lic.) | E181: Isole | F181: G. Bianchi | G181: 18 | H181: 500 | I181: 120 | J181: =H181*G181 -> 9000 | K181: =I181*G181 -> 2160 | L181: =J181-K181 -> 6840 | M181: =IF(AND(J181<>0, K181<>0), Table1[[#This Row],[PROFIT MARGIN (eur)]]/K181, 0) -> 3.1666667
J183: RICAVI COMPLESSIVI | K183: COSTI COMPLESSIVI | L183: UTILE TOTALE | M183: MARGINE PROFITTO TOTALE
J184: =SUM(Table1[TOT_REVENUE]) -> 873007.25 | K184: =SUM(Table1[TOT_COST]) -> 329543 | L184: =J184-K184 -> 543464.25 | M184: =L184/J184 -> 0.62251974

Sheet PIVOT_TABLE
A3: Row Labels | B3: Sum of TOT_REVENUE | C3: Sum of TOT_COST | D3: Sum of PROFIT MARGIN (eur) | E3: Sum of PROFIT MARGIN (%)
A4: Arredo | B4: 161714 | C4: 100422 | D4: 61292 | E4: 0.18681959
A5: Sedia Operativa Mesh | B5: 71910 | C5: 46530 | D5: 25380 | E5: 0.036121114
A6: Supporto Monitor Doppio | B6: 28066.5 | C6: 13152 | D6: 14914.5 | E6: 0.073998115
A7: Scrivania Ergonomica | B7: 45425 | C7: 32960 | D7: 12465 | E7: 0.015677567
A8: Lampada LED Scrivania | B8: 16312.5 | C8: 7780 | D8: 8532.5 | E8: 0.061022791
A9: Elettronica | B9: 152346.75 | C9: 88736 | D9: 63610.75 | E9: 0.18270279
A10: Tastiera Meccanica RGB | B10: 32532.75 | C10: 14800 | D10: 17732.75 | E10: 0.066586902
A11: Monitor 27" 4K | B11: 48992 | C11: 33180 | D11: 15812 | E11: 0.011988248
A12: Smart Hub X1 | B12: 30756 | C12: 20100 | D12: 10656 | E12: 0.028459059
A13: Webcam Full HD | B13: 18463.25 | C13: 8596 | D13: 9867.25 | E13: 0.0466825
A14: Auricolari Wireless Pro | B14: 21602.75 | C14: 12060 | D14: 9542.75 | E14: 0.028986079
A15: Software | B15: 558946.5 | C15: 140385 | D15: 418561.5 | E15: 0.63047762
... A19: Grand Total | B19: 873007.25 | C19: 329543 | D19: 543464.25 | E19: 1
A26: Row Labels | B26: Sum of PROFIT MARGIN (eur) | C26: Average of PROFIT MARGIN (%)
A27: Nord | B27: 148826.25 | C27: 1.0985459
A28: Isole | B28: 140685.25 | C28: 1.0352835
A29: Sud | B29: 133154 | C29: 0.92842931
A30: Centro | B30: 120798.75 | C30: 0.92412007
A31: Grand Total | B31: 543464.25 | C31: 1

Sheet GRAFICI
B2: PRODOTTI | C2: Sum of PROFIT MARGIN (eur) | D2: Average of PROFIT MARGIN (%)
B3: Lampada LED Scrivania | C3: 8532.5 | D3: 0.73227349
B4: Auricolari Wireless Pro | C4: 9542.75 | D4: 0.52174942
B5: Webcam Full HD | C5: 9867.25 | D5: 0.76389546
B6: Smart Hub X1 | C6: 10656 | D6: 0.34150871
B7: Scrivania Ergonomica | C7: 12465 | D7: 0.256542
B8: Antivirus Enterprise (Lic.) | C8: 13464 | D8: 1.8201289
B9: Supporto Monitor Doppio | C9: 14914.5 | D9: 0.73998115
B10: Monitor 27" 4K | C10: 15812 | D10: 0.30826925
B11: Tastiera Meccanica RGB | C11: 17732.75 | D11: 0.79904282
B12: Sedia Operativa Mesh | C12: 25380 | D12: 0.36121114
B13: Suite Cloud Business (Lic.) | C13: 197020 | D13: 1.8416295
B14: ERP Module Analytics (Lic.) | C14: 208077.5 | D14: 2.0472052
B15: Grand Total | C15: 543464.25 | D15: 1
