Workbook
Name ID_ARTICOLI: Table1[]
Name TOT_PRODUZIONE: Table2[]

Sheet RAW_Dump_Produzione
A1: ID_ORDINE_PROD | B1: DATA_INIZIO_PROG | C1: LINEA_PRODUZIONE | D1: CODICE_ARTICOLO | E1: DESCRIZIONE_ARTICOLO | F1: QTA_LOTTO | G1: QTA_PRODOTTA_EFF | H1: QTA_SCARTO | I1: COSTO_STD_UNITARIO | J1: COSTO_EFF_UNITARIO | K1: CAUSALE_SCARTO
A2: ODP-2026-1114 | B2: 04-10-2026 | C2: Linea 2 - Assemblaggio | D2: ART-MEC-01 | E2: Albero di Trasmissione Precisione | F2: 100 | G2: 80 | H2: 20 | I2: 45 | J2: 41.65 | K2: Tolleranza Fuori Limite
A3: ODP-2026-1165 | B3: 2026-11-17 | C3: Linea 2 - Assemblaggio | D3: ART-ASS-01 | E3: Gruppo Valvola Idraulica Completa | F3: 150 | G3: 148 | H3: 2 | I3: 120 | J3: 117.05 | K3: Usura Utensile
A4: ODP-2026-1170 | B4: 21/11/2026 | C4: Linea 2 - Assemblaggio | D4: ART-ASS-01 | E4: Gruppo Valvola Idraulica Completa | F4: 100 | G4: 90 | H4: 10 | I4: 120 | J4: 116.87 | K4: Difetto Materia Prima
A5: ODP-2026-1102 | B5: 24/09/2026 | C5: Linea 1 - Meccanica | D5: ART-ELE-02 | E5: Sensore di Pressione Digitale High-Temp | F5: 150 | G5: 130 | H5: 20 | I5: 65 | J5: 61.71
A6: ODP-2026-1101 | B6: 2026-09-23 | C6: LINEA 3 - ELETTRONICA | D6: ART-ELE-01 | E6: Scheda Controllo Inverter 400V | F6: 500 | G6: 493 | H6: 7 | I6: 210 | J6: 203.19 | K6: Difetto Materia Prima
A7: ODP-2026-1016 | B7: 2026-07-13 | C7: Linea 3 - Elettronica | D7: ART-ASS-01 | E7: Gruppo Valvola Idraulica Completa | F7: 1000 | G7: 920 | H7: 80 | I7: 120 | J7: 115.37 | K7: Problema Saldatura/Smt
A8: ODP-2026-1178 | B8: 28/11/2026 | C8: Linea 2 - Assemblaggio | D8: ART-ASS-03 | E8: Modulo Riduttore Epicroidale | F8: 500 | G8: 485 | H8: 15 | I8: 150 | J8: 144.9 | K8: Tolleranza Fuori Limite
A9: ODP-2026-1036 | B9: 30-07-2026 | C9: Linea 3 - Elettronica | D9: ART-MEC-03 | E9: Flangia Acciaio Inox 120mm | F9: 500 | G9: 484 | H9: 16 | I9: 35 | J9: 38.08 | K9: Difetto Materia Prima
A10: ODP-2026-1120 | B10: 10/10/2026 | C10: LINEA 1 - MECCANICA | D10: ART-MEC-03 | E10: Flangia Acciaio Inox 120mm | F10: 200 | G10: 184 | H10: 16 | I10: 35 | J10: 38.58 | K10: Difetto Materia Prima
A11: ODP-2026-1153 | B11: 2026-11-07 | C11: Linea 3 - Elettronica | D11: ART-MEC-01 | E11: Albero di Trasmissione Precisione | F11: 200 | G11: 182 | H11: 18 | I11: 45 | J11: 43.96 | K11: Difetto Materia Prima
A12: ODP-2026-1025 | B12: 21/07/2026 | C12: LINEA 3 - ELETTRONICA | D12: ART-MEC-01 | E12: Albero di Trasmissione Precisione | F12: 200 | G12: 196 | H12: 4 | I12: 45 | J12: 45.49 | K12: Errore Set-up Macchina
A13: ODP-2026-1077 | B13: 03-09-2026 | C13: Linea 3 - Elettronica | D13: ART-ELE-03 | E13: Quadro Comando Touch 10'' Industrial | F13: 250 | G13: 228 | H13: 22 | I13: 340 | J13: 354.02 | K13: Errore Set-up Macchina
A14: ODP-2026-1157 | B14: 10/11/2026 | C14: LINEA 1 - MECCANICA | D14: ART-MEC-03 | E14: Flangia Acciaio Inox 120mm | F14: 300 | G14: 285 | H14: 15 | I14: 35 | J14: 40.44 | K14: Problema Saldatura/Smt
A15: ODP-2026-1119 | B15: 09-10-2026 | C15: LINEA 1 - MECCANICA | D15: ART-ASS-03 | E15: Modulo Riduttore Epicroidale | F15: 150 | G15: 137 | H15: 13 | I15: 150 | J15: 144.92 | K15: Errore Set-up Macchina
A16: ODP-2026-1069 | B16: 2026-08-27 | C16: Linea 1 - Meccanica | D16: ART-ASS-01 | E16: Gruppo Valvola Idraulica Completa | F16: 150 | G16: 129 | H16: 21 | I16: 120 | J16: 113.38 | K16: Tolleranza Fuori Limite
A17: ODP-2026-1017 | B17: 14/07/2026 | C17: Linea 1 - Meccanica | D17: ART-ELE-02 | E17: Sensore di Pressione Digitale High-Temp | F17: 100 | G17: 85 | H17: 15 | I17: 65 | J17: 61.83 | K17: Difetto Materia Prima
... A35: ODP-2026-1112 | B35: 2026-10-03 | C35: Linea 3 - Elettronica | D35: ART-ASS-03 | E35: Modulo Riduttore Epicroidale | F35: 100 | G35: 77 | H35: 23 | I35: 150 | J35: 145.94 | K35: Problema Saldatura/Smt
A36: ODP-2026-1046 | B36: 08/08/2026 | C36: Linea 1 - Meccanica | D36: ART-ELE-03 | E36: Quadro Comando Touch 10'' Industrial | F36: 300 | H36: 24 | I36: 340 | J36: 356.11 | K36: Usura Utensile
A37: ODP-2026-1068 | B37: 26-08-2026 | C37: linea 2 - assemblaggio | D37: ART-MEC-01 | E37: Albero di Trasmissione Precisione | F37: 1000 | G37: 993 | H37: 7 | I37: 45 | J37: 42.06
A38: ODP-2026-1162 | B38: 14/11/2026 | C38: Linea 1 - Meccanica | D38: ART-ELE-02 | E38: Sensore di Pressione Digitale High-Temp | F38: 300 | G38: 287 | H38: 13 | I38: 65 | J38: 61.78 | K38: Errore Set-up Macchina
A39: ODP-2026-1030 | B39: 2026-07-25 | C39: Linea 2 - Assemblaggio | D39: ART-MEC-02 | E39: Ingranaggio Elicoidale Z45 | F39: 100 | G39: 84 | H39: 16 | I39: 28 | J39: 25.62 | K39: Errore Set-up Macchina
A40: ODP-2026-1124 | B40: 2026-10-13 | C40: Linea 3 - Elettronica | D40: ART-ELE-01 | E40: Scheda Controllo Inverter 400V | F40: 250 | G40: 244 | H40: 6 | I40: 210 | J40: 206.23 | K40: Problema Saldatura/Smt
A41: ODP-2026-1136 | B41: 23/10/2026 | C41: Linea 3 - Elettronica | D41: ART-ELE-02 | E41: Sensore di Pressione Digitale High-Temp | F41: 300 | G41: 276 | H41: 24 | I41: 65 | J41: 61.5 | K41: Errore Set-up Macchina
A42: ODP-2026-1151 | B42: 05-11-2026 | C42: linea 2 - assemblaggio | D42: ART-ELE-03 | E42: Quadro Comando Touch 10'' Industrial | F42: 100 | G42: 92 | H42: 8 | I42: 340 | J42: 357.88 | K42: Tolleranza Fuori Limite
A43: ODP-2026-1032 | B43: 2026-07-27 | C43: Linea 2 - Assemblaggio | D43: ART-ELE-01 | E43: Scheda Controllo Inverter 400V | F43: 1000 | G43: 981 | H43: 19 | I43: 210 | J43: 205.72 | K43: Difetto Materia Prima
A44: ODP-2026-1013 | B44: 11-07-2026 | C44: linea 2 - assemblaggio | D44: ART-ELE-01 | E44: Scheda Controllo Inverter 400V | F44: 500 | G44: 479 | H44: 21 | I44: 210 | J44: 203.37
A45: ODP-2026-1042 | B45: 04/08/2026 | C45: Linea 3 - Elettronica | D45: ART-ELE-02 | E45: Sensore di Pressione Digitale High-Temp | F45: 500 | G45: 492 | H45: 8 | I45: 65 | J45: 62.25 | K45: Tolleranza Fuori Limite
A46: ODP-2026-1052 | B46: 13-08-2026 | C46: Linea 1 - Meccanica | D46: ART-MEC-01 | E46: Albero di Trasmissione Precisione | F46: 100 | G46: 86 | H46: 14 | I46: 45 | J46: 41.25 | K46: Difetto Materia Prima
A47: ODP-2026-1057 | B47: 2026-08-17 | C47: Linea 3 - Elettronica | D47: ART-ELE-01 | E47: Scheda Controllo Inverter 400V | F47: 100 | G47: 77 | H47: 23 | I47: 210 | J47: 203.77 | K47: Errore Set-up Macchina
A48: ODP-2026-1094 | B48: 17/09/2026 | C48: LINEA 3 - ELETTRONICA | D48: ART-ASS-02 | E48: Attuatore Pneumatico Bi-Stadio | F48: 150 | G48: 129 | H48: 21 | I48: 85 | J48: 92.05 | K48: Difetto Materia Prima
A49: ODP-2026-1091 | B49: 2026-09-15 | C49: Linea 2 - Assemblaggio | D49: ART-ELE-01 | E49: Scheda Controllo Inverter 400V | F49: 300 | G49: 276 | H49: 24 | I49: 210 | J49: 208.08 | K49: Errore Set-up Macchina
A50: ODP-2026-1067 | B50: 2026-08-26 | C50: Linea 1 - Meccanica | D50: ART-MEC-01 | E50: Albero di Trasmissione Precisione | F50: 1000 | G50: 994 | H50: 6 | I50: 45 | J50: 44.24 | K50: Problema Saldatura/Smt
A51: ODP-2026-1039 | B51: 02/08/2026 | C51: LINEA 1 - MECCANICA | D51: ART-ASS-01 | E51: Gruppo Valvola Idraulica Completa | F51: 300 | G51: 289 | H51: 11 | I51: 120 | J51: 115.76 | K51: Problema Saldatura/Smt
A52: ODP-2026-1056 | B52: 16-08-2026 | C52: Linea 2 - Assemblaggio | D52: ART-MEC-01 | E52: Albero di Trasmissione Precisione | F52: 500 | G52: 484 | H52: 16 | I52: 45 | J52: 45.02 | K52: Errore Set-up Macchina
A53: ODP-2026-1099 | B53: 2026-09-22 | C53: LINEA 1 - MECCANICA | D53: ART-MEC-01 | E53: Albero di Trasmissione Precisione | F53: 250 | G53: 227 | H53: 23 | I53: 45 | J53: 43.18 | K53: Tolleranza Fuori Limite
A54: ODP-2026-1154 | B54: 07/11/2026 | C54: linea 2 - assemblaggio | D54: ART-ASS-02 | E54: Attuatore Pneumatico Bi-Stadio | F54: 200 | G54: 194 | H54: 6 | I54: 85 | J54: 91.43 | K54: Tolleranza Fuori Limite
A55: ODP-2026-1097 | B55: 20/09/2026 | C55: Linea 3 - Elettronica | D55: ART-MEC-02 | E55: Ingranaggio Elicoidale Z45 | F55: 1000 | G55: 984 | H55: 16 | I55: 28 | J55: 29.52 | K55: Difetto Materia Prima
A56: ODP-2026-1003 | B56: 02-07-2026 | C56: LINEA 1 - MECCANICA | D56: ART-ASS-02 | E56: Attuatore Pneumatico Bi-Stadio | F56: 100 | G56: 77 | H56: 23 | I56: 85 | J56: 89.49 | K56: Tolleranza Fuori Limite
A57: ODP-2026-1113 | B57: 04-10-2026 | C57: Linea 2 - Assemblaggio | D57: ART-ASS-01 | E57: Gruppo Valvola Idraulica Completa | F57: 500 | H57: 5 | I57: 120 | J57: 114.01 | K57: Usura Utensile
...

Sheet CLEAN_Dump_Produzione
A1: ID_ORDINE_PROD | B1: DATA_INIZIO_PROG | C1: LINEA_PRODUZIONE | D1: CODICE_ARTICOLO | E1: DESCRIZIONE_ARTICOLO | F1: QTA_LOTTO | G1: QTA_PRODOTTA_EFF | H1: QTA_SCARTO | I1: COSTO_STD_UNITARIO | J1: COSTO_EFF_UNITARIO | K1: CAUSALE_SCARTO | L1: TOT_STD_COST (€) | M1: TOT_EFF_COST (€) | N1: Scostamento dei Costi / Cost Variance (€) | O1: Tasso di Scarto / Scrap Rate (%):
A2: ODP-2026-1114 | B2: 46299 | C2: Linea 2 - Assemblaggio | D2: ART-MEC-01 | E2: Albero di Trasmissione Precisione | F2: 100 | G2: 80 | H2: 20 | I2: 45 | J2: 41.65 | K2: Tolleranza Fuori Limite | L2: =Table2[[#This Row],[QTA_LOTTO]]*Table2[[#This Row],[COSTO_STD_UNITARIO]] -> 4500 | M2: =Table2[[#This Row],[QTA_PRODOTTA_EFF]]*Table2[[#This Row],[COSTO_EFF_UNITARIO]] -> 3332 | N2: =Table2[[#This Row],[TOT_EFF_COST (€)]]-Table2[[#This Row],[TOT_STD_COST (€)]] -> -1168 | O2: =Table2[[#This Row],[QTA_SCARTO]]/Table2[[#This Row],[QTA_LOTTO]] -> 0.2
A3: ODP-2026-1165 | B3: 46343 | C3: Linea 2 - Assemblaggio | D3: ART-ASS-01 | E3: Gruppo Valvola Idraulica Completa | F3: 150 | G3: 148 | H3: 2 | I3: 120 | J3: 117.05 | K3: Usura Utensile | L3: =Table2[[#This Row],[QTA_LOTTO]]*Table2[[#This Row],[COSTO_STD_UNITARIO]] -> 18000 | M3: =Table2[[#This Row],[QTA_PRODOTTA_EFF]]*Table2[[#This Row],[COSTO_EFF_UNITARIO]] -> 17323.4 | N3: =Table2[[#This Row],[TOT_EFF_COST (€)]]-Table2[[#This Row],[TOT_STD_COST (€)]] -> -676.6 | O3: =Table2[[#This Row],[QTA_SCARTO]]/Table2[[#This Row],[QTA_LOTTO]] -> 0.013333333
A4: ODP-2026-1170 | B4: 46347 | C4: Linea 2 - Assemblaggio | D4: ART-ASS-01 | E4: Gruppo Valvola Idraulica Completa | F4: 100 | G4: 90 | H4: 10 | I4: 120 | J4: 116.87 | K4: Difetto Materia Prima | L4: =Table2[[#This Row],[QTA_LOTTO]]*Table2[[#This Row],[COSTO_STD_UNITARIO]] -> 12000 | M4: =Table2[[#This Row],[QTA_PRODOTTA_EFF]]*Table2[[#This Row],[COSTO_EFF_UNITARIO]] -> 10518.3 | N4: =Table2[[#This Row],[TOT_EFF_COST (€)]]-Table2[[#This Row],[TOT_STD_COST (€)]] -> -1481.7 | O4: =Table2[[#This Row],[QTA_SCARTO]]/Table2[[#This Row],[QTA_LOTTO]] -> 0.1
A5: ODP-2026-1102 | B5: 46289 | C5: Linea 1 - Meccanica | D5: ART-ELE-02 | E5: Sensore di Pressione Digitale High-Temp | F5: 150 | G5: 130 | H5: 20 | I5: 65 | J5: 61.71 | K5: Non Definito | L5: =Table2[[#This Row],[QTA_LOTTO]]*Table2[[#This Row],[COSTO_STD_UNITARIO]] -> 9750 | M5: =Table2[[#This Row],[QTA_PRODOTTA_EFF]]*Table2[[#This Row],[COSTO_EFF_UNITARIO]] -> 8022.3 | N5: =Table2[[#This Row],[TOT_EFF_COST (€)]]-Table2[[#This Row],[TOT_STD_COST (€)]] -> -1727.7 | O5: =Table2[[#This Row],[QTA_SCARTO]]/Table2[[#This Row],[QTA_LOTTO]] -> 0.13333333
A6: ODP-2026-1101 | B6: 46288 | C6: Linea 3 - Elettronica | D6: ART-ELE-01 | E6: Scheda Controllo Inverter 400V | F6: 500 | G6: 493 | H6: 7 | I6: 210 | J6: 203.19 | K6: Difetto Materia Prima | L6: =Table2[[#This Row],[QTA_LOTTO]]*Table2[[#This Row],[COSTO_STD_UNITARIO]] -> 105000 | M6: =Table2[[#This Row],[QTA_PRODOTTA_EFF]]*Table2[[#This Row],[COSTO_EFF_UNITARIO]] -> 100172.67 | N6: =Table2[[#This Row],[TOT_EFF_COST (€)]]-Table2[[#This Row],[TOT_STD_COST (€)]] -> -4827.33 | O6: =Table2[[#This Row],[QTA_SCARTO]]/Table2[[#This Row],[QTA_LOTTO]] -> 0.014
A7: ODP-2026-1016 | B7: 46216 | C7: Linea 3 - Elettronica | D7: ART-ASS-01 | E7: Gruppo Valvola Idraulica Completa | F7: 1000 | G7: 920 | H7: 80 | I7: 120 | J7: 115.37 | K7: Problema Saldatura/Smt | L7: =Table2[[#This Row],[QTA_LOTTO]]*Table2[[#This Row],[COSTO_STD_UNITARIO]] -> 120000 | M7: =Table2[[#This Row],[QTA_PRODOTTA_EFF]]*Table2[[#This Row],[COSTO_EFF_UNITARIO]] -> 106140.4 | N7: =Table2[[#This Row],[TOT_EFF_COST (€)]]-Table2[[#This Row],[TOT_STD_COST (€)]] -> -13859.6 | O7: =Table2[[#This Row],[QTA_SCARTO]]/Table2[[#This Row],[QTA_LOTTO]] -> 0.08
A8: ODP-2026-1178 | B8: 46354 | C8: Linea 2 - Assemblaggio | D8: ART-ASS-03 | E8: Modulo Riduttore Epicroidale | F8: 500 | G8: 485 | H8: 15 | I8: 150 | J8: 144.9 | K8: Tolleranza Fuori Limite | L8: =Table2[[#This Row],[QTA_LOTTO]]*Table2[[#This Row],[COSTO_STD_UNITARIO]] -> 75000 | M8: =Table2[[#This Row],[QTA_PRODOTTA_EFF]]*Table2[[#This Row],[COSTO_EFF_UNITARIO]] -> 70276.5 | N8: =Table2[[#This Row],[TOT_EFF_COST (€)]]-Table2[[#This Row],[TOT_STD_COST (€)]] -> -4723.5 | O8: =Table2[[#This Row],[QTA_SCARTO]]/Table2[[#This Row],[QTA_LOTTO]] -> 0.03
A9: ODP-2026-1036 | B9: 46233 | C9: Linea 3 - Elettronica | D9: ART-MEC-03 | E9: Flangia Acciaio Inox 120mm | F9: 500 | G9: 484 | H9: 16 | I9: 35 | J9: 38.08 | K9: Difetto Materia Prima | L9: =Table2[[#This Row],[QTA_LOTTO]]*Table2[[#This Row],[COSTO_STD_UNITARIO]] -> 17500 | M9: =Table2[[#This Row],[QTA_PRODOTTA_EFF]]*Table2[[#This Row],[COSTO_EFF_UNITARIO]] -> 18430.72 | N9: =Table2[[#This Row],[TOT_EFF_COST (€)]]-Table2[[#This Row],[TOT_STD_COST (€)]] -> 930.72 | O9: =Table2[[#This Row],[QTA_SCARTO]]/Table2[[#This Row],[QTA_LOTTO]] -> 0.032
A10: ODP-2026-1120 | B10: 46305 | C10: Linea 1 - Meccanica | D10: ART-MEC-03 | E10: Flangia Acciaio Inox 120mm | F10: 200 | G10: 184 | H10: 16 | I10: 35 | J10: 38.58 | K10: Difetto Materia Prima | L10: =Table2[[#This Row],[QTA_LOTTO]]*Table2[[#This Row],[COSTO_STD_UNITARIO]] -> 7000 | M10: =Table2[[#This Row],[QTA_PRODOTTA_EFF]]*Table2[[#This Row],[COSTO_EFF_UNITARIO]] -> 7098.72 | N10: =Table2[[#This Row],[TOT_EFF_COST (€)]]-Table2[[#This Row],[TOT_STD_COST (€)]] -> 98.72 | O10: =Table2[[#This Row],[QTA_SCARTO]]/Table2[[#This Row],[QTA_LOTTO]] -> 0.08
A11: ODP-2026-1153 | B11: 46333 | C11: Linea 3 - Elettronica | D11: ART-MEC-01 | E11: Albero di Trasmissione Precisione | F11: 200 | G11: 182 | H11: 18 | I11: 45 | J11: 43.96 | K11: Difetto Materia Prima | L11: =Table2[[#This Row],[QTA_LOTTO]]*Table2[[#This Row],[COSTO_STD_UNITARIO]] -> 9000 | M11: =Table2[[#This Row],[QTA_PRODOTTA_EFF]]*Table2[[#This Row],[COSTO_EFF_UNITARIO]] -> 8000.72 | N11: =Table2[[#This Row],[TOT_EFF_COST (€)]]-Table2[[#This Row],[TOT_STD_COST (€)]] -> -999.28 | O11: =Table2[[#This Row],[QTA_SCARTO]]/Table2[[#This Row],[QTA_LOTTO]] -> 0.09
A12: ODP-2026-1025 | B12: 46224 | C12: Linea 3 - Elettronica | D12: ART-MEC-01 | E12: Albero di Trasmissione Precisione | F12: 200 | G12: 196 | H12: 4 | I12: 45 | J12: 45.49 | K12: Errore Set-up Macchina | L12: =Table2[[#This Row],[QTA_LOTTO]]*Table2[[#This Row],[COSTO_STD_UNITARIO]] -> 9000 | M12: =Table2[[#This Row],[QTA_PRODOTTA_EFF]]*Table2[[#This Row],[COSTO_EFF_UNITARIO]] -> 8916.04 | N12: =Table2[[#This Row],[TOT_EFF_COST (€)]]-Table2[[#This Row],[TOT_STD_COST (€)]] -> -83.96 | O12: =Table2[[#This Row],[QTA_SCARTO]]/Table2[[#This Row],[QTA_LOTTO]] -> 0.02
A13: ODP-2026-1077 | B13: 46268 | C13: Linea 3 - Elettronica | D13: ART-ELE-03 | E13: Quadro Comando Touch 10'' Industrial | F13: 250 | G13: 228 | H13: 22 | I13: 340 | J13: 354.02 | K13: Errore Set-up Macchina | L13: =Table2[[#This Row],[QTA_LOTTO]]*Table2[[#This Row],[COSTO_STD_UNITARIO]] -> 85000 | M13: =Table2[[#This Row],[QTA_PRODOTTA_EFF]]*Table2[[#This Row],[COSTO_EFF_UNITARIO]] -> 80716.56 | N13: =Table2[[#This Row],[TOT_EFF_COST (€)]]-Table2[[#This Row],[TOT_STD_COST (€)]] -> -4283.44 | O13: =Table2[[#This Row],[QTA_SCARTO]]/Table2[[#This Row],[QTA_LOTTO]] -> 0.088
... A34: ODP-2026-1112 | B34: 46298 | C34: Linea 3 - Elettronica | D34: ART-ASS-03 | E34: Modulo Riduttore Epicroidale | F34: 100 | G34: 77 | H34: 23 | I34: 150 | J34: 145.94 | K34: Problema Saldatura/Smt | L34: =Table2[[#This Row],[QTA_LOTTO]]*Table2[[#This Row],[COSTO_STD_UNITARIO]] -> 15000 | M34: =Table2[[#This Row],[QTA_PRODOTTA_EFF]]*Table2[[#This Row],[COSTO_EFF_UNITARIO]] -> 11237.38 | N34: =Table2[[#This Row],[TOT_EFF_COST (€)]]-Table2[[#This Row],[TOT_STD_COST (€)]] -> -3762.62 | O34: =Table2[[#This Row],[QTA_SCARTO]]/Table2[[#This Row],[QTA_LOTTO]] -> 0.23
A35: ODP-2026-1046 | B35: 46242 | C35: Linea 1 - Meccanica | D35: ART-ELE-03 | E35: Quadro Comando Touch 10'' Industrial | F35: 300 | G35: =CLEAN_Dump_Produzione!$F35-CLEAN_Dump_Produzione!$H35 -> 276 | H35: 24 | I35: 340 | J35: 356.11 | K35: Usura Utensile | L35: =Table2[[#This Row],[QTA_LOTTO]]*Table2[[#This Row],[COSTO_STD_UNITARIO]] -> 102000 | M35: =Table2[[#This Row],[QTA_PRODOTTA_EFF]]*Table2[[#This Row],[COSTO_EFF_UNITARIO]] -> 98286.36 | N35: =Table2[[#This Row],[TOT_EFF_COST (€)]]-Table2[[#This Row],[TOT_STD_COST (€)]] -> -3713.64 | O35: =Table2[[#This Row],[QTA_SCARTO]]/Table2[[#This Row],[QTA_LOTTO]] -> 0.08
A36: ODP-2026-1068 | B36: 46260 | C36: Linea 2 - Assemblaggio | D36: ART-MEC-01 | E36: Albero di Trasmissione Precisione | F36: 1000 | G36: 993 | H36: 7 | I36: 45 | J36: 42.06 | K36: Non Definito | L36: =Table2[[#This Row],[QTA_LOTTO]]*Table2[[#This Row],[COSTO_STD_UNITARIO]] -> 45000 | M36: =Table2[[#This Row],[QTA_PRODOTTA_EFF]]*Table2[[#This Row],[COSTO_EFF_UNITARIO]] -> 41765.58 | N36: =Table2[[#This Row],[TOT_EFF_COST (€)]]-Table2[[#This Row],[TOT_STD_COST (€)]] -> -3234.42 | O36: =Table2[[#This Row],[QTA_SCARTO]]/Table2[[#This Row],[QTA_LOTTO]] -> 0.007
A37: ODP-2026-1162 | B37: 46340 | C37: Linea 1 - Meccanica | D37: ART-ELE-02 | E37: Sensore di Pressione Digitale High-Temp | F37: 300 | G37: 287 | H37: 13 | I37: 65 | J37: 61.78 | K37: Errore Set-up Macchina | L37: =Table2[[#This Row],[QTA_LOTTO]]*Table2[[#This Row],[COSTO_STD_UNITARIO]] -> 19500 | M37: =Table2[[#This Row],[QTA_PRODOTTA_EFF]]*Table2[[#This Row],[COSTO_EFF_UNITARIO]] -> 17730.86 | N37: =Table2[[#This Row],[TOT_EFF_COST (€)]]-Table2[[#This Row],[TOT_STD_COST (€)]] -> -1769.14 | O37: =Table2[[#This Row],[QTA_SCARTO]]/Table2[[#This Row],[QTA_LOTTO]] -> 0.043333333
A38: ODP-2026-1030 | B38: 46228 | C38: Linea 2 - Assemblaggio | D38: ART-MEC-02 | E38: Ingranaggio Elicoidale Z45 | F38: 100 | G38: 84 | H38: 16 | I38: 28 | J38: 25.62 | K38: Errore Set-up Macchina | L38: =Table2[[#This Row],[QTA_LOTTO]]*Table2[[#This Row],[COSTO_STD_UNITARIO]] -> 2800 | M38: =Table2[[#This Row],[QTA_PRODOTTA_EFF]]*Table2[[#This Row],[COSTO_EFF_UNITARIO]] -> 2152.08 | N38: =Table2[[#This Row],[TOT_EFF_COST (€)]]-Table2[[#This Row],[TOT_STD_COST (€)]] -> -647.92 | O38: =Table2[[#This Row],[QTA_SCARTO]]/Table2[[#This Row],[QTA_LOTTO]] -> 0.16
A39: ODP-2026-1124 | B39: 46308 | C39: Linea 3 - Elettronica | D39: ART-ELE-01 | E39: Scheda Controllo Inverter 400V | F39: 250 | G39: 244 | H39: 6 | I39: 210 | J39: 206.23 | K39: Problema Saldatura/Smt | L39: =Table2[[#This Row],[QTA_LOTTO]]*Table2[[#This Row],[COSTO_STD_UNITARIO]] -> 52500 | M39: =Table2[[#This Row],[QTA_PRODOTTA_EFF]]*Table2[[#This Row],[COSTO_EFF_UNITARIO]] -> 50320.12 | N39: =Table2[[#This Row],[TOT_EFF_COST (€)]]-Table2[[#This Row],[TOT_STD_COST (€)]] -> -2179.88 | O39: =Table2[[#This Row],[QTA_SCARTO]]/Table2[[#This Row],[QTA_LOTTO]] -> 0.024
A40: ODP-2026-1136 | B40: 46318 | C40: Linea 3 - Elettronica | D40: ART-ELE-02 | E40: Sensore di Pressione Digitale High-Temp | F40: 300 | G40: 276 | H40: 24 | I40: 65 | J40: 61.5 | K40: Errore Set-up Macchina | L40: =Table2[[#This Row],[QTA_LOTTO]]*Table2[[#This Row],[COSTO_STD_UNITARIO]] -> 19500 | M40: =Table2[[#This Row],[QTA_PRODOTTA_EFF]]*Table2[[#This Row],[COSTO_EFF_UNITARIO]] -> 16974 | N40: =Table2[[#This Row],[TOT_EFF_COST (€)]]-Table2[[#This Row],[TOT_STD_COST (€)]] -> -2526 | O40: =Table2[[#This Row],[QTA_SCARTO]]/Table2[[#This Row],[QTA_LOTTO]] -> 0.08
A41: ODP-2026-1151 | B41: 46331 | C41: Linea 2 - Assemblaggio | D41: ART-ELE-03 | E41: Quadro Comando Touch 10'' Industrial | F41: 100 | G41: 92 | H41: 8 | I41: 340 | J41: 357.88 | K41: Tolleranza Fuori Limite | L41: =Table2[[#This Row],[QTA_LOTTO]]*Table2[[#This Row],[COSTO_STD_UNITARIO]] -> 34000 | M41: =Table2[[#This Row],[QTA_PRODOTTA_EFF]]*Table2[[#This Row],[COSTO_EFF_UNITARIO]] -> 32924.96 | N41: =Table2[[#This Row],[TOT_EFF_COST (€)]]-Table2[[#This Row],[TOT_STD_COST (€)]] -> -1075.04 | O41: =Table2[[#This Row],[QTA_SCARTO]]/Table2[[#This Row],[QTA_LOTTO]] -> 0.08
A42: ODP-2026-1032 | B42: 46230 | C42: Linea 2 - Assemblaggio | D42: ART-ELE-01 | E42: Scheda Controllo Inverter 400V | F42: 1000 | G42: 981 | H42: 19 | I42: 210 | J42: 205.72 | K42: Difetto Materia Prima | L42: =Table2[[#This Row],[QTA_LOTTO]]*Table2[[#This Row],[COSTO_STD_UNITARIO]] -> 210000 | M42: =Table2[[#This Row],[QTA_PRODOTTA_EFF]]*Table2[[#This Row],[COSTO_EFF_UNITARIO]] -> 201811.32 | N42: =Table2[[#This Row],[TOT_EFF_COST (€)]]-Table2[[#This Row],[TOT_STD_COST (€)]] -> -8188.68 | O42: =Table2[[#This Row],[QTA_SCARTO]]/Table2[[#This Row],[QTA_LOTTO]] -> 0.019
A43: ODP-2026-1013 | B43: 46214 | C43: Linea 2 - Assemblaggio | D43: ART-ELE-01 | E43: Scheda Controllo Inverter 400V | F43: 500 | G43: 479 | H43: 21 | I43: 210 | J43: 203.37 | K43: Non Definito | L43: =Table2[[#This Row],[QTA_LOTTO]]*Table2[[#This Row],[COSTO_STD_UNITARIO]] -> 105000 | M43: =Table2[[#This Row],[QTA_PRODOTTA_EFF]]*Table2[[#This Row],[COSTO_EFF_UNITARIO]] -> 97414.23 | N43: =Table2[[#This Row],[TOT_EFF_COST (€)]]-Table2[[#This Row],[TOT_STD_COST (€)]] -> -7585.77 | O43: =Table2[[#This Row],[QTA_SCARTO]]/Table2[[#This Row],[QTA_LOTTO]] -> 0.042
A44: ODP-2026-1042 | B44: 46238 | C44: Linea 3 - Elettronica | D44: ART-ELE-02 | E44: Sensore di Pressione Digitale High-Temp | F44: 500 | G44: 492 | H44: 8 | I44: 65 | J44: 62.25 | K44: Tolleranza Fuori Limite | L44: =Table2[[#This Row],[QTA_LOTTO]]*Table2[[#This Row],[COSTO_STD_UNITARIO]] -> 32500 | M44: =Table2[[#This Row],[QTA_PRODOTTA_EFF]]*Table2[[#This Row],[COSTO_EFF_UNITARIO]] -> 30627 | N44: =Table2[[#This Row],[TOT_EFF_COST (€)]]-Table2[[#This Row],[TOT_STD_COST (€)]] -> -1873 | O44: =Table2[[#This Row],[QTA_SCARTO]]/Table2[[#This Row],[QTA_LOTTO]] -> 0.016
A45: ODP-2026-1052 | B45: 46247 | C45: Linea 1 - Meccanica | D45: ART-MEC-01 | E45: Albero di Trasmissione Precisione | F45: 100 | G45: 86 | H45: 14 | I45: 45 | J45: 41.25 | K45: Difetto Materia Prima | L45: =Table2[[#This Row],[QTA_LOTTO]]*Table2[[#This Row],[COSTO_STD_UNITARIO]] -> 4500 | M45: =Table2[[#This Row],[QTA_PRODOTTA_EFF]]*Table2[[#This Row],[COSTO_EFF_UNITARIO]] -> 3547.5 | N45: =Table2[[#This Row],[TOT_EFF_COST (€)]]-Table2[[#This Row],[TOT_STD_COST (€)]] -> -952.5 | O45: =Table2[[#This Row],[QTA_SCARTO]]/Table2[[#This Row],[QTA_LOTTO]] -> 0.14
A46: ODP-2026-1057 | B46: 46251 | C46: Linea 3 - Elettronica | D46: ART-ELE-01 | E46: Scheda Controllo Inverter 400V | F46: 100 | G46: 77 | H46: 23 | I46: 210 | J46: 203.77 | K46: Errore Set-up Macchina | L46: =Table2[[#This Row],[QTA_LOTTO]]*Table2[[#This Row],[COSTO_STD_UNITARIO]] -> 21000 | M46: =Table2[[#This Row],[QTA_PRODOTTA_EFF]]*Table2[[#This Row],[COSTO_EFF_UNITARIO]] -> 15690.29 | N46: =Table2[[#This Row],[TOT_EFF_COST (€)]]-Table2[[#This Row],[TOT_STD_COST (€)]] -> -5309.71 | O46: =Table2[[#This Row],[QTA_SCARTO]]/Table2[[#This Row],[QTA_LOTTO]] -> 0.23
A47: ODP-2026-1094 | B47: 46282 | C47: Linea 3 - Elettronica | D47: ART-ASS-02 | E47: Attuatore Pneumatico Bi-Stadio | F47: 150 | G47: 129 | H47: 21 | I47: 85 | J47: 92.05 | K47: Difetto Materia Prima | L47: =Table2[[#This Row],[QTA_LOTTO]]*Table2[[#This Row],[COSTO_STD_UNITARIO]] -> 12750 | M47: =Table2[[#This Row],[QTA_PRODOTTA_EFF]]*Table2[[#This Row],[COSTO_EFF_UNITARIO]] -> 11874.45 | N47: =Table2[[#This Row],[TOT_EFF_COST (€)]]-Table2[[#This Row],[TOT_STD_COST (€)]] -> -875.55 | O47: =Table2[[#This Row],[QTA_SCARTO]]/Table2[[#This Row],[QTA_LOTTO]] -> 0.14
... A55: ODP-2026-1003 | B55: 46205 | C55: Linea 1 - Meccanica | D55: ART-ASS-02 | E55: Attuatore Pneumatico Bi-Stadio | F55: 100 | G55: 77 | H55: 23 | I55: 85 | J55: 89.49 | K55: Tolleranza Fuori Limite | L55: =Table2[[#This Row],[QTA_LOTTO]]*Table2[[#This Row],[COSTO_STD_UNITARIO]] -> 8500 | M55: =Table2[[#This Row],[QTA_PRODOTTA_EFF]]*Table2[[#This Row],[COSTO_EFF_UNITARIO]] -> 6890.73 | N55: =Table2[[#This Row],[TOT_EFF_COST (€)]]-Table2[[#This Row],[TOT_STD_COST (€)]] -> -1609.27 | O55: =Table2[[#This Row],[QTA_SCARTO]]/Table2[[#This Row],[QTA_LOTTO]] -> 0.23
A56: ODP-2026-1113 | B56: 46299 | C56: Linea 2 - Assemblaggio | D56: ART-ASS-01 | E56: Gruppo Valvola Idraulica Completa | F56: 500 | G56: =CLEAN_Dump_Produzione!$F56-CLEAN_Dump_Produzione!$H56 -> 495 | H56: 5 | I56: 120 | J56: 114.01 | K56: Usura Utensile | L56: =Table2[[#This Row],[QTA_LOTTO]]*Table2[[#This Row],[COSTO_STD_UNITARIO]] -> 60000 | M56: =Table2[[#This Row],[QTA_PRODOTTA_EFF]]*Table2[[#This Row],[COSTO_EFF_UNITARIO]] -> 56434.95 | N56: =Table2[[#This Row],[TOT_EFF_COST (€)]]-Table2[[#This Row],[TOT_STD_COST (€)]] -> -3565.05 | O56: =Table2[[#This Row],[QTA_SCARTO]]/Table2[[#This Row],[QTA_LOTTO]] -> 0.01
A57: ODP-2026-1047 | B57: 46243 | C57: Linea 2 - Assemblaggio | D57: ART-ASS-01 | E57: Gruppo Valvola Idraulica Completa | F57: 300 | G57: 279 | H57: 21 | I57: 120 | J57: 116.94 | K57: Problema Saldatura/Smt | L57: =Table2[[#This Row],[QTA_LOTTO]]*Table2[[#This Row],[COSTO_STD_UNITARIO]] -> 36000 | M57: =Table2[[#This Row],[QTA_PRODOTTA_EFF]]*Table2[[#This Row],[COSTO_EFF_UNITARIO]] -> 32626.26 | N57: =Table2[[#This Row],[TOT_EFF_COST (€)]]-Table2[[#This Row],[TOT_STD_COST (€)]] -> -3373.74 | O57: =Table2[[#This Row],[QTA_SCARTO]]/Table2[[#This Row],[QTA_LOTTO]] -> 0.07
A58: ODP-2026-1066 | B58: 46259 | C58: Linea 1 - Meccanica | D58: ART-ELE-03 | E58: Quadro Comando Touch 10'' Industrial | F58: 250 | G58: 240 | H58: 10 | I58: 340 | J58: 356.58 | K58: Problema Saldatura/Smt | L58: =Table2[[#This Row],[QTA_LOTTO]]*Table2[[#This Row],[COSTO_STD_UNITARIO]] -> 85000 | M58: =Table2[[#This Row],[QTA_PRODOTTA_EFF]]*Table2[[#This Row],[COSTO_EFF_UNITARIO]] -> 85579.2 | N58: =Table2[[#This Row],[TOT_EFF_COST (€)]]-Table2[[#This Row],[TOT_STD_COST (€)]] -> 579.2 | O58: =Table2[[#This Row],[QTA_SCARTO]]/Table2[[#This Row],[QTA_LOTTO]] -> 0.04
A59: ODP-2026-1061 | B59: 46254 | C59: Linea 1 - Meccanica | D59: ART-MEC-01 | E59: Albero di Trasmissione Precisione | F59: 250 | G59: 230 | H59: 20 | I59: 45 | J59: 43.26 | K59: Tolleranza Fuori Limite | L59: =Table2[[#This Row],[QTA_LOTTO]]*Table2[[#This Row],[COSTO_STD_UNITARIO]] -> 11250 | M59: =Table2[[#This Row],[QTA_PRODOTTA_EFF]]*Table2[[#This Row],[COSTO_EFF_UNITARIO]] -> 9949.8 | N59: =Table2[[#This Row],[TOT_EFF_COST (€)]]-Table2[[#This Row],[TOT_STD_COST (€)]] -> -1300.2 | O59: =Table2[[#This Row],[QTA_SCARTO]]/Table2[[#This Row],[QTA_LOTTO]] -> 0.08
A60: ODP-2026-1019 | B60: 46219 | C60: Linea 1 - Meccanica | D60: ART-MEC-03 | E60: Flangia Acciaio Inox 120mm | F60: 300 | G60: 285 | H60: 15 | I60: 35 | J60: 39.82 | K60: Tolleranza Fuori Limite | L60: =Table2[[#This Row],[QTA_LOTTO]]*Table2[[#This Row],[COSTO_STD_UNITARIO]] -> 10500 | M60: =Table2[[#This Row],[QTA_PRODOTTA_EFF]]*Table2[[#This Row],[COSTO_EFF_UNITARIO]] -> 11348.7 | N60: =Table2[[#This Row],[TOT_EFF_COST (€)]]-Table2[[#This Row],[TOT_STD_COST (€)]] -> 848.7 | O60: =Table2[[#This Row],[QTA_SCARTO]]/Table2[[#This Row],[QTA_LOTTO]] -> 0.05
A61: ODP-2026-1179 | B61: 46355 | C61: Linea 1 - Meccanica | D61: ART-MEC-02 | E61: Ingranaggio Elicoidale Z45 | F61: 150 | G61: 145 | H61: 5 | I61: 28 | J61: 28.76 | K61: Problema Saldatura/Smt | L61: =Table2[[#This Row],[QTA_LOTTO]]*Table2[[#This Row],[COSTO_STD_UNITARIO]] -> 4200 | M61: =Table2[[#This Row],[QTA_PRODOTTA_EFF]]*Table2[[#This Row],[COSTO_EFF_UNITARIO]] -> 4170.2 | N61: =Table2[[#This Row],[TOT_EFF_COST (€)]]-Table2[[#This Row],[TOT_STD_COST (€)]] -> -29.8 | O61: =Table2[[#This Row],[QTA_SCARTO]]/Table2[[#This Row],[QTA_LOTTO]] -> 0.033333333
A62: ODP-2026-1027 | B62: 46226 | C62: Linea 1 - Meccanica | D62: ART-ELE-02 | E62: Sensore di Pressione Digitale High-Temp | F62: 300 | G62: 276 | H62: 24 | I62: 65 | J62: 63.89 | K62: Tolleranza Fuori Limite | L62: =Table2[[#This Row],[QTA_LOTTO]]*Table2[[#This Row],[COSTO_STD_UNITARIO]] -> 19500 | M62: =Table2[[#This Row],[QTA_PRODOTTA_EFF]]*Table2[[#This Row],[COSTO_EFF_UNITARIO]] -> 17633.64 | N62: =Table2[[#This Row],[TOT_EFF_COST (€)]]-Table2[[#This Row],[TOT_STD_COST (€)]] -> -1866.36 | O62: =Table2[[#This Row],[QTA_SCARTO]]/Table2[[#This Row],[QTA_LOTTO]] -> 0.08
A63: ODP-2026-1160 | B63: 46339 | C63: Linea 3 - Elettronica | D63: ART-ELE-02 | E63: Sensore di Pressione Digitale High-Temp | F63: 200 | G63: 190 | H63: 10 | I63: 65 | J63: 60.78 | K63: Problema Saldatura/Smt | L63: =Table2[[#This Row],[QTA_LOTTO]]*Table2[[#This Row],[COSTO_STD_UNITARIO]] -> 13000 | M63: =Table2[[#This Row],[QTA_PRODOTTA_EFF]]*Table2[[#This Row],[COSTO_EFF_UNITARIO]] -> 11548.2 | N63: =Table2[[#This Row],[TOT_EFF_COST (€)]]-Table2[[#This Row],[TOT_STD_COST (€)]] -> -1451.8 | O63: =Table2[[#This Row],[QTA_SCARTO]]/Table2[[#This Row],[QTA_LOTTO]] -> 0.05
A64: ODP-2026-1105 | B64: 46292 | C64: Linea 3 - Elettronica | D64: ART-MEC-02 | E64: Ingranaggio Elicoidale Z45 | F64: 500 | G64: 488 | H64: 12 | I64: 28 | J64: 25.71 | K64: Problema Saldatura/Smt | L64: =Table2[[#This Row],[QTA_LOTTO]]*Table2[[#This Row],[COSTO_STD_UNITARIO]] -> 14000 | M64: =Table2[[#This Row],[QTA_PRODOTTA_EFF]]*Table2[[#This Row],[COSTO_EFF_UNITARIO]] -> 12546.48 | N64: =Table2[[#This Row],[TOT_EFF_COST (€)]]-Table2[[#This Row],[TOT_STD_COST (€)]] -> -1453.52 | O64: =Table2[[#This Row],[QTA_SCARTO]]/Table2[[#This Row],[QTA_LOTTO]] -> 0.024
A65: ODP-2026-1118 | B65: 46303 | C65: Linea 3 - Elettronica | D65: ART-ASS-01 | E65: Gruppo Valvola Idraulica Completa | F65: 1000 | G65: 982 | H65: 18 | I65: 120 | J65: 117.4 | K65: Difetto Materia Prima | L65: =Table2[[#This Row],[QTA_LOTTO]]*Table2[[#This Row],[COSTO_STD_UNITARIO]] -> 120000 | M65: =Table2[[#This Row],[QTA_PRODOTTA_EFF]]*Table2[[#This Row],[COSTO_EFF_UNITARIO]] -> 115286.8 | N65: =Table2[[#This Row],[TOT_EFF_COST (€)]]-Table2[[#This Row],[TOT_STD_COST (€)]] -> -4713.2 | O65: =Table2[[#This Row],[QTA_SCARTO]]/Table2[[#This Row],[QTA_LOTTO]] -> 0.018
A66: ODP-2026-1037 | B66: 46234 | C66: Linea 1 - Meccanica | D66: ART-ELE-03 | E66: Quadro Comando Touch 10'' Industrial | F66: 250 | G66: 226 | H66: 24 | I66: 340 | J66: 355.51 | K66: Errore Set-up Macchina | L66: =Table2[[#This Row],[QTA_LOTTO]]*Table2[[#This Row],[COSTO_STD_UNITARIO]] -> 85000 | M66: =Table2[[#This Row],[QTA_PRODOTTA_EFF]]*Table2[[#This Row],[COSTO_EFF_UNITARIO]] -> 80345.26 | N66: =Table2[[#This Row],[TOT_EFF_COST (€)]]-Table2[[#This Row],[TOT_STD_COST (€)]] -> -4654.74 | O66: =Table2[[#This Row],[QTA_SCARTO]]/Table2[[#This Row],[QTA_LOTTO]] -> 0.096
A67: ODP-2026-1125 | B67: 46309 | C67: Linea 2 - Assemblaggio | D67: ART-MEC-03 | E67: Flangia Acciaio Inox 120mm | F67: 150 | G67: 138 | H67: 12 | I67: 35 | J67: 37.62 | K67: Difetto Materia Prima | L67: =Table2[[#This Row],[QTA_LOTTO]]*Table2[[#This Row],[COSTO_STD_UNITARIO]] -> 5250 | M67: =Table2[[#This Row],[QTA_PRODOTTA_EFF]]*Table2[[#This Row],[COSTO_EFF_UNITARIO]] -> 5191.56 | N67: =Table2[[#This Row],[TOT_EFF_COST (€)]]-Table2[[#This Row],[TOT_STD_COST (€)]] -> -58.44 | O67: =Table2[[#This Row],[QTA_SCARTO]]/Table2[[#This Row],[QTA_LOTTO]] -> 0.08
...

Sheet ID_ARTICOLI
A1: CODICE_ARTICOLO | B1: DESCRIZIONE_ARTICOLO | D1: CAUSALE_SCARTO | F1: LINEA_PRODUZIONE
A2: ART-ASS-01 | B2: Gruppo Valvola Idraulica Completa | D2: Tolleranza Fuori Limite | F2: Linea 2 - Assemblaggio
A3: ART-ASS-02 | B3: Attuatore Pneumatico Bi-Stadio | D3: Usura Utensile | F3: Linea 2 - Assemblaggio
A4: ART-ASS-03 | B4: Modulo Riduttore Epicroidale | D4: Difetto Materia Prima | F4: Linea 1 - Meccanica
A5: ART-ELE-01 | B5: Scheda Controllo Inverter 400V | D5: Non Definito | F5: Linea 3 - Elettronica
A6: ART-ELE-02 | B6: Sensore di Pressione Digitale High-Temp | D6: Problema Saldatura/Smt | F6: Linea 1 - Meccanica
A7: ART-ELE-03 | B7: Quadro Comando Touch 10'' Industrial | D7: Errore Set-up Macchina
A8: ART-MEC-01 | B8: Albero di Trasmissione Precisione
A9: ART-MEC-02 | B9: Ingranaggio Elicoidale Z45
A10: ART-MEC-03 | B10: Flangia Acciaio Inox 120mm

Sheet PIVOT
A1: Row Labels | B1: TOT_EFF_COST | C1: TOT_COST_VARIANCE(€) | D1: AVG_SCRAP_RATE
A2: Linea 1 - Meccanica | B2: 2535434.6 | C2: -83265.37 | D2: 0.060948718
A3: ART-ASS-01 | B3: 573480.21 | C3: -38519.79 | D3: 0.044444444
A4: ART-ASS-02 | B4: 321990.8 | C4: 7490.8 | D4: 0.056166667 | F4: Sum of QTA_SCARTO | G4: Column Labels
A5: ART-ASS-03 | B5: 176083.28 | C5: -18916.72 | D5: 0.083571429 | F5: Row Labels | G5: Linea 1 - Meccanica | H5: Linea 2 - Assemblaggio | I5: Linea 3 - Elettronica | J5: Grand Total
A6: ART-ELE-01 | B6: 423227.86 | C6: -17772.14 | D6: 0.03 | F6: Difetto Materia Prima | G6: 0.17900552 | H6: 0.1849711 | I6: 0.21618357 | J6: 0.19340206
A7: ART-ELE-02 | B7: 67469.99 | C7: -7280.01 | D7: 0.082666667 | F7: Errore Set-up Macchina | G7: 0.19668508 | H7: 0.36705202 | I7: 0.21135266 | J7: 0.25030928
A8: ART-ELE-03 | B8: 656127.42 | C8: -6872.58 | D8: 0.069904762 | F8: Non Definito | G8: 0.064088398 | H8: 0.040462428 | I8: 0 | J8: 0.035463918
A9: ART-MEC-01 | B9: 93614.61 | C9: -5385.39 | D9: 0.066666667 | F9: Problema Saldatura/Smt | G9: 0.14696133 | H9: 0.1849711 | I9: 0.30555556 | J9: 0.21195876
A10: ART-MEC-02 | B10: 62476.22 | C10: -4723.78 | D10: 0.05847619 | F10: Tolleranza Fuori Limite | G10: 0.29392265 | H10: 0.16473988 | I10: 0.055555556 | J10: 0.1756701
A11: ART-MEC-03 | B11: 160964.24 | C11: 8714.24 | D11: 0.055794872 | F11: Usura Utensile | G11: 0.11933702 | H11: 0.057803468 | I11: 0.21135266 | J11: 0.13319588
A12: Linea 2 - Assemblaggio | B12: 2122124.8 | C12: -88175.22 | D12: 0.059185792 | F12: Grand Total | G12: 1 | H12: 1 | I12: 1 | J12: 1
A13: ART-ASS-01 | B13: 186735.86 | C13: -17264.14 | D13: 0.057291667
A14: ART-ASS-02 | B14: 343452.75 | C14: 11952.75 | D14: 0.029037037
A15: ART-ASS-03 | B15: 142155.08 | C15: -7844.92 | D15: 0.018333333
A16: ART-ELE-01 | B16: 707881.78 | C16: -48118.22 | D16: 0.053
A17: ART-ELE-02 | B17: 39124.43 | C17: -3125.57 | D17: 0.04775
A18: ART-ELE-03 | B18: 517273.47 | C18: -9726.53 | D18: 0.075714286
A19: ART-MEC-01 | B19: 140996.52 | C19: -12003.48 | D19: 0.073636364
A20: ART-MEC-02 | B20: 15055.04 | C20: -1744.96 | D20: 0.086166667
A21: ART-MEC-03 | B21: 29449.85 | C21: -300.15 | D21: 0.086
A22: Linea 3 - Elettronica | B22: 2508331.7 | C22: -69018.26 | D22: 0.064191358
A23: ART-ASS-01 | B23: 349942.7 | C23: -28057.3 | D23: 0.050533333
A24: ART-ASS-02 | B24: 174471.55 | C24: -4028.45 | D24: 0.090277778
... A32: Grand Total | B32: 7165891.2 | C32: -240458.85 | D32: 0.061324074

Sheet CHARTS
A4: Row Labels | B4: Sum of Scostamento dei Costi / Cost Variance (€) | C4: Sum of Scostamento dei Costi / Cost Variance (€)2
A5: Linea 1 - Meccanica | B5: 0.346277 | C5: -83265.37 | I5: Row Labels | J5: Sum of Scostamento dei Costi / Cost Variance (€)
A6: Linea 2 - Assemblaggio | B6: 0.36669567 | C6: -88175.22 | I6: Linea 1 - Meccanica | J6: 0.346277
A7: Linea 3 - Elettronica | B7: 0.28702732 | C7: -69018.26 | I7: Linea 2 - Assemblaggio | J7: 0.36669567
A8: Grand Total | B8: 1 | C8: -240458.85 | I8: Linea 3 - Elettronica | J8: 0.28702732
I9: Grand Total | J9: 1
A23: Row Labels | B23: Sum of QTA_SCARTO
A24: Difetto Materia Prima | B24: 469
A25: Errore Set-up Macchina | B25: 607
A26: Non Definito | B26: 86
A27: Problema Saldatura/Smt | B27: 514
A28: Tolleranza Fuori Limite | B28: 426
A29: Usura Utensile | B29: 323
A30: Grand Total | B30: 2425
